Workbook
Name m_avg_dd_episode: Data!$C$24:$E$24
Name m_avg_holding_sessions: Data!$C$40:$E$40
Name m_avg_loss: Data!$C$36:$E$36
Name m_avg_trade_net: Data!$C$34:$E$34
Name m_avg_win: Data!$C$35:$E$35
Name m_bench_cagr: Data!$C$10:$E$10
Name m_bench_max_dd: Data!$C$23:$E$23
Name m_bench_sharpe_rf0: Data!$C$18:$E$18
Name m_bench_sharpe_rf6: Data!$C$19:$E$19
Name m_bench_total_return: Data!$C$9:$E$9
Name m_bench_vol: Data!$C$15:$E$15
Name m_best_trade: Data!$C$38:$E$38
Name m_beta: Data!$C$26:$E$26
Name m_cagr: Data!$C$8:$E$8
Name m_calmar: Data!$C$21:$E$21
Name m_capacity_1pct_50fit_cr: Data!$C$46:$E$46
Name m_capacity_1pct_90fit_cr: Data!$C$44:$E$44
Name m_capacity_5pct_90fit_cr: Data!$C$45:$E$45
Name m_cvar95_daily: Data!$C$28:$E$28
Name m_end: Data!$C$5:$E$5
Name m_excess_cagr: Data!$C$11:$E$11
Name m_excess_kurt_daily: Data!$C$30:$E$30
Name m_longest_dd_sessions: Data!$C$25:$E$25
Name m_max_dd: Data!$C$22:$E$22
Name m_mean_trade_xs_nifty: Data!$C$13:$E$13
Name m_mean_trade_xs_univ_60d: Data!$C$12:$E$12
Name m_median_adv20_cr: Data!$C$42:$E$42
Name m_p10_adv20_cr: Data!$C$43:$E$43
Name m_payoff: Data!$C$37:$E$37
Name m_profit_factor: Data!$C$33:$E$33
Name m_sharpe_rf0: Data!$C$16:$E$16
Name m_sharpe_rf6: Data!$C$17:$E$17
Name m_skew_daily: Data!$C$29:$E$29
Name m_sortino_rf0: Data!$C$20:$E$20
Name m_start: Data!$C$4:$E$4
Name m_total_return: Data!$C$7:$E$7
Name m_trades: Data!$C$31:$E$31
Name m_turnover_one_way: Data!$C$41:$E$41
Name m_var95_daily: Data!$C$27:$E$27
Name m_vol: Data!$C$14:$E$14
Name m_win_rate: Data!$C$32:$E$32
Name m_worst_trade: Data!$C$39:$E$39
Name m_years: Data!$C$6:$E$6
Name PeriodHeaders: Data!$C$3:$E$3
Name SelPeriod: Cover!$L$3

Sheet Cover
A1: StackFlow PEAD V2 — Post-Earnings-Announcement Drift, NSE
A2: Thesis: Indian stocks with the largest point-in-time earnings surprise (ex-ante SUE, top quintile) keep drifting up for ~60 trading days after the filing; a 30-slot long-only non-financial book tries to harvest it.
A3: FORWARD-TEST CANDIDATE — NOT VALIDATED | F3: Generated 2026-09-23 | K3: View period ▸ | L3: Full Period | N3: ="Window: "&INDEX(m_start,1,MATCH(SelPeriod,PeriodHeaders,0))&" to "&INDEX(m_end,1,MATCH(SelPeriod,PeriodHeaders,0)) -> Window: 2021-08-11 to 2026-08-11
A5: =INDEX(m_cagr,1,MATCH(SelPeriod,PeriodHeaders,0)) -> 0.17155034 | C5: =INDEX(m_excess_cagr,1,MATCH(SelPeriod,PeriodHeaders,0)) -> 0.058715761 | E5: =INDEX(m_sharpe_rf0,1,MATCH(SelPeriod,PeriodHeaders,0)) -> 1.0827253
A7: CAGR | C7: Excess CAGR vs NIFTY 500 (price index)* | E7: Sharpe (rf = 0%)
A9: =INDEX(m_max_dd,1,MATCH(SelPeriod,PeriodHeaders,0)) -> -0.23675278 | C9: =INDEX(m_win_rate,1,MATCH(SelPeriod,PeriodHeaders,0)) -> 0.58377425 | E9: =INDEX(m_trades,1,MATCH(SelPeriod,PeriodHeaders,0)) -> 567
A11: Maximum drawdown | C11: Win rate (net of costs) | E11: Total trades
A12: KPI cards follow the period selector in L3 (Full Period / Discovery / Holdout). Charts show the full-period book with the two periods shaded.
A15: Discovery vs Holdout — the honesty check
A16: Metric | C16: Full Period | D16: Discovery | E16: Holdout | F16: Holdout, calendar split
A17: CAGR | C17: =Data!C8 -> 0.17155034 | D17: =Data!D8 -> 0.23156402 | E17: =Data!E8 -> 0.087085033 | F17: =Data!G8 -> 0.13045486
A18: NIFTY 500 (PR) CAGR | C18: =Data!C10 -> 0.11283458 | D18: =Data!D10 -> 0.1518874 | E18: =Data!E10 -> 0.07893447 | F18: =Data!G10 -> 0.078543654
A19: Excess CAGR vs NIFTY 500* | C19: =Data!C11 -> 0.058715761 | D19: =Data!D11 -> 0.079676621 | E19: =Data!E11 -> 0.0081505638 | F19: =Data!G11 -> 0.051911208
A20: Sharpe (rf = 0%) | C20: =Data!C16 -> 1.0827253 | D20: =Data!D16 -> 1.5005549 | E20: =Data!E16 -> 0.59298964 | F20: =Data!G16 -> 0.81859279
A21: NIFTY 500 Sharpe (rf = 0%) | C21: =Data!C18 -> 0.82364982 | D21: =Data!D18 -> 1.092487 | E21: =Data!E18 -> 0.59416204 | F21: =Data!G18 -> 0.59360632
A22: Sharpe (rf = 6%) | C22: =Data!C17 -> 0.72013335 | D22: =Data!D17 -> 1.1080203 | E22: =Data!E17 -> 0.24400845 | F22: =Data!G17 -> 0.47639337
A23: Maximum drawdown | C23: =Data!C22 -> -0.23675278 | D23: =Data!D22 -> -0.19281551 | E23: =Data!E22 -> -0.24950465 | F23: =Data!G22 -> -0.23675278
A24: Trades | C24: =Data!C31 -> 567 | D24: =Data!D31 -> 277 | E24: =Data!E31 -> 296 | F24: n/a
A25: Holdout = a book holding ONLY trades signalled on/after 2024-01-01, started empty. The calendar split of the continuous book (last column) looks better only because Q4-2023 discovery trades still open in Jan–Feb 2024 averaged +22% net; it is shown for transparency, not as holdout evidence. Holdout Sharpe equals the index's. The 2024–26 window was already seen by V1, the V2 grid and the exit-rule study, so it cannot validate the strategy.
A31: *Benchmark is the NIFTY 500 PRICE index; strategy prices are dividend-adjusted (yfinance auto_adjust). No NIFTY 500 TRI series is available in the repository, so every excess figure is overstated by roughly the index dividend yield (~1.0–1.5 pp/yr); holdout excess vs a TRI is ≈ 0% or below. Costs: 0.585% round trip on every trade (0.2925% per leg, LeadFlow NSE cost model). Status: forward-test candidate — NOT a validated live strategy. The only remaining clean test is the forward record (forward_record_pead_v2.csv).
A38: Source: corrected/period_metrics_corrected.csv, corrected/nav_daily_corrected.csv · Built from CORRECTED_REPORT.md (revision 2) outputs · Workbook generated 2026-09-23

Sheet Executive Summary
A1: Executive Summary — full KPI table (as at last completed trade, 2026-08-11)
A2: Status: FORWARD-TEST CANDIDATE — NOT VALIDATED. Discovery and Holdout are trade-attributed books (each holds only the trades signalled in its own period). Excess figures are vs the NIFTY 500 PRICE index (see Methodology).
A4: Metric | B4: Full Period | C4: Discovery | D4: Holdout | E4: Holdout, calendar split (flattered)
A5: Window
A6: Window start | B6: =Data!C4 -> 2021-08-11 | C6: =Data!D4 -> 2021-08-11 | D6: =Data!E4 -> 2024-01-17 | E6: =Data!G4 -> 2023-12-29
A7: Window end | B7: =Data!C5 -> 2026-08-11 | C7: =Data!D5 -> 2024-02-13 | D7: =Data!E5 -> 2026-08-11 | E7: =Data!G5 -> 2026-08-11
A8: Years | B8: =Data!C6 -> 4.9993155 | C8: =Data!D6 -> 2.5078713 | D8: =Data!E6 -> 2.5653662 | E8: =Data!G6 -> 2.6173854
A9: Return
A10: Total return | B10: =Data!C7 -> 1.2067733 | C10: =Data!D7 -> 0.68598808 | D10: =Data!E7 -> 0.23887988 | E10: =Data!G7 -> 0.3784284
A11: CAGR | B11: =Data!C8 -> 0.17155034 | C11: =Data!D8 -> 0.23156402 | D11: =Data!E8 -> 0.087085033 | E11: =Data!G8 -> 0.13045486
A12: NIFTY 500 (PR) CAGR | B12: =Data!C10 -> 0.11283458 | C12: =Data!D10 -> 0.1518874 | D12: =Data!E10 -> 0.07893447 | E12: =Data!G10 -> 0.078543654
A13: Excess CAGR vs NIFTY 500 (PR) | B13: =Data!C11 -> 0.058715761 | C13: =Data!D11 -> 0.079676621 | D13: =Data!E11 -> 0.0081505638 | E13: =Data!G11 -> 0.051911208
A14: Mean trade excess vs same-month event universe (60d) | B14: =Data!C12 -> 0.010602259 | C14: =Data!D12 -> 0.0033915041 | D14: =Data!E12 -> 0.010788755 | E14: n/a
A15: Mean trade excess vs NIFTY 500 (per trade) | B15: =Data!C13 -> 0.022942353 | C15: =Data!D13 -> 0.029213073 | D15: =Data!E13 -> 0.010525723 | E15: n/a
A16: Risk
A17: Annualised volatility | B17: =Data!C14 -> 0.16071962 | C17: =Data!D14 -> 0.14845989 | D17: =Data!E14 -> 0.16698793 | E17: =Data!G14 -> 0.17029732
A18: NIFTY 500 volatility | B18: =Data!C15 -> 0.14477536 | C18: =Data!D15 -> 0.14061415 | D18: =Data!E15 -> 0.14890391 | E18: =Data!G15 -> 0.14822808
A19: Sharpe (rf = 0%) | B19: =Data!C16 -> 1.0827253 | C19: =Data!D16 -> 1.5005549 | D19: =Data!E16 -> 0.59298964 | E19: =Data!G16 -> 0.81859279
A20: Sharpe (rf = 6%) | B20: =Data!C17 -> 0.72013335 | C20: =Data!D17 -> 1.1080203 | D20: =Data!E17 -> 0.24400845 | E20: =Data!G17 -> 0.47639337
A21: NIFTY 500 Sharpe (rf = 0%) | B21: =Data!C18 -> 0.82364982 | C21: =Data!D18 -> 1.092487 | D21: =Data!E18 -> 0.59416204 | E21: =Data!G18 -> 0.59360632
A22: NIFTY 500 Sharpe (rf = 6%) | B22: =Data!C19 -> 0.42112521 | C22: =Data!D19 -> 0.67805043 | D22: =Data!E19 -> 0.20279793 | E22: =Data!G19 -> 0.20045785
A23: Sortino (rf = 0%) | B23: =Data!C20 -> 1.4756578 | C23: =Data!D20 -> 2.0515544 | D23: =Data!E20 -> 0.80115462 | E23: =Data!G20 -> 1.1154854
A24: Calmar (CAGR / |max DD|) | B24: =Data!C21 -> 0.72459696 | C24: =Data!D21 -> 1.2009616 | D24: =Data!E21 -> 0.3490317 | E24: =Data!G21 -> 0.55101724
A25: Maximum drawdown | B25: =Data!C22 -> -0.23675278 | C25: =Data!D22 -> -0.19281551 | D25: =Data!E22 -> -0.24950465 | E25: =Data!G22 -> -0.23675278
A26: NIFTY 500 maximum drawdown | B26: =Data!C23 -> -0.18843201 | C26: =Data!D23 -> -0.18477731 | D26: =Data!E23 -> -0.18843201 | E26: =Data!G23 -> -0.18843201
A27: Average drawdown (mean episode trough) | B27: =Data!C24 -> -0.027338901 | C27: =Data!D24 -> -0.020194367 | D27: =Data!E24 -> -0.033755378 | E27: =Data!G24 -> -0.037260221
A28: Longest drawdown (trading sessions) | B28: =Data!C25 -> 423 | C28: =Data!D25 -> 184 | D28: =Data!E25 -> 431 | E28: =Data!G25 -> 423
A29: Beta to NIFTY 500 (daily) | B29: =Data!C26 -> 0.94573016 | C29: =Data!D26 -> 0.87303271 | D29: =Data!E26 -> 0.97843988 | E29: =Data!G26 -> 1.0002074
A30: Trades
A31: Total trades | B31: =Data!C31 -> 567 | C31: =Data!D31 -> 277 | D31: =Data!E31 -> 296 | E31: n/a
A32: Win rate | B32: =Data!C32 -> 0.58377425 | C32: =Data!D32 -> 0.59205776 | D32: =Data!E32 -> 0.56418919 | E32: n/a
A33: Profit factor | B33: =Data!C33 -> 2.0928063 | C33: =Data!D33 -> 2.670276 | D33: =Data!E33 -> 1.5129575 | E33: n/a
A34: Average net trade | B34: =Data!C34 -> 0.046084937 | C34: =Data!D34 -> 0.062456471 | D34: =Data!E34 -> 0.024053236 | E34: n/a
A35: Average win | B35: =Data!C35 -> 0.15118194 | C35: =Data!D35 -> 0.16864803 | D35: =Data!E35 -> 0.12574598 | E35: n/a
A36: Average loss | B36: =Data!C36 -> -0.10131806 | C36: =Data!D36 -> -0.091662251 | D36: =Data!E36 -> -0.10759551 | E36: n/a
A37: Payoff ratio (avg win / |avg loss|) | B37: =Data!C37 -> 1.4921519 | C37: =Data!D37 -> 1.8398853 | D37: =Data!E37 -> 1.1686917 | E37: n/a
A38: Best trade | B38: =Data!C38 -> 0.67123276 | C38: =Data!D38 -> 0.67123276 | D38: =Data!E38 -> 0.66616176 | E38: n/a
A39: Worst trade | B39: =Data!C39 -> -0.58684997 | C39: =Data!D39 -> -0.31865708 | D39: =Data!E39 -> -0.58684997 | E39: n/a
A40: Average holding period (sessions) | B40: =Data!C40 -> 60 | C40: =Data!D40 -> 60 | D40: =Data!E40 -> 60 | E40: n/a
A41: Capacity & turnover
...

Sheet Performance Charts
A1: Performance Charts
A2: Forward-test candidate — not validated. Shaded bands: Discovery (2021-08 → 2023-12) and Holdout (2024-01 →).
A4: 1 · Equity curve (full history, rebased to 100) with Discovery / Holdout bands
A24: 2 · Underwater curve (same period, same x-axis)
A40: 3 · Rolling 12-month excess return vs NIFTY 500
A56: 4 · Monthly returns heatmap — strategy (full-period book)
A57: Strategy monthly return (YTD / Annual = calendar-year return; 2021 from 11-Aug, 2026 to 11-Aug)
A58: Year | B58: Jan | C58: Feb | D58: Mar | E58: Apr | F58: May | G58: Jun | H58: Jul | I58: Aug | J58: Sep | K58: Oct | L58: Nov | M58: Dec | N58: YTD / Annual | O58: NIFTY 500 | P58: Excess
A59: 2021 | B59: =IF(COUNTIFS(Data!$U$4:$U$64,2021,Data!$V$4:$V$64,1)=0,"",SUMIFS(Data!$W$4:$W$64,Data!$U$4:$U$64,2021,Data!$V$4:$V$64,1)) | C59: =IF(COUNTIFS(Data!$U$4:$U$64,2021,Data!$V$4:$V$64,2)=0,"",SUMIFS(Data!$W$4:$W$64,Data!$U$4:$U$64,2021,Data!$V$4:$V$64,2)) | D59: =IF(COUNTIFS(Data!$U$4:$U$64,2021,Data!$V$4:$V$64,3)=0,"",SUMIFS(Data!$W$4:$W$64,Data!$U$4:$U$64,2021,Data!$V$4:$V$64,3)) | E59: =IF(COUNTIFS(Data!$U$4:$U$64,2021,Data!$V$4:$V$64,4)=0,"",SUMIFS(Data!$W$4:$W$64,Data!$U$4:$U$64,2021,Data!$V$4:$V$64,4)) | F59: =IF(COUNTIFS(Data!$U$4:$U$64,2021,Data!$V$4:$V$64,5)=0,"",SUMIFS(Data!$W$4:$W$64,Data!$U$4:$U$64,2021,Data!$V$4:$V$64,5)) | G59: =IF(COUNTIFS(Data!$U$4:$U$64,2021,Data!$V$4:$V$64,6)=0,"",SUMIFS(Data!$W$4:$W$64,Data!$U$4:$U$64,2021,Data!$V$4:$V$64,6)) | H59: =IF(COUNTIFS(Data!$U$4:$U$64,2021,Data!$V$4:$V$64,7)=0,"",SUMIFS(Data!$W$4:$W$64,Data!$U$4:$U$64,2021,Data!$V$4:$V$64,7)) | I59: =IF(COUNTIFS(Data!$U$4:$U$64,2021,Data!$V$4:$V$64,8)=0,"",SUMIFS(Data!$W$4:$W$64,Data!$U$4:$U$64,2021,Data!$V$4:$V$64,8)) -> 0.017963758 | J59: =IF(COUNTIFS(Data!$U$4:$U$64,2021,Data!$V$4:$V$64,9)=0,"",SUMIFS(Data!$W$4:$W$64,Data!$U$4:$U$64,2021,Data!$V$4:$V$64,9)) -> 0.0078607844 | K59: =IF(COUNTIFS(Data!$U$4:$U$64,2021,Data!$V$4:$V$64,10)=0,"",SUMIFS(Data!$W$4:$W$64,Data!$U$4:$U$64,2021,Data!$V$4:$V$64,10)) -> -0.024465098 | L59: =IF(COUNTIFS(Data!$U$4:$U$64,2021,Data!$V$4:$V$64,11)=0,"",SUMIFS(Data!$W$4:$W$64,Data!$U$4:$U$64,2021,Data!$V$4:$V$64,11)) -> 0.033369901 | M59: =IF(COUNTIFS(Data!$U$4:$U$64,2021,Data!$V$4:$V$64,12)=0,"",SUMIFS(Data!$W$4:$W$64,Data!$U$4:$U$64,2021,Data!$V$4:$V$64,12)) -> 0.036147431 | N59: =INDEX(Data!$AC$4:$AC$9,MATCH(2021,Data!$AA$4:$AA$9,0)) -> 0.071650172 | O59: =INDEX(Data!$AD$4:$AD$9,MATCH(2021,Data!$AA$4:$AA$9,0)) -> 0.080686482 | P59: =INDEX(Data!$AE$4:$AE$9,MATCH(2021,Data!$AA$4:$AA$9,0)) -> -0.0090363098
A60: 2022 | B60: =IF(COUNTIFS(Data!$U$4:$U$64,2022,Data!$V$4:$V$64,1)=0,"",SUMIFS(Data!$W$4:$W$64,Data!$U$4:$U$64,2022,Data!$V$4:$V$64,1)) -> 0.0014163193 | C60: =IF(COUNTIFS(Data!$U$4:$U$64,2022,Data!$V$4:$V$64,2)=0,"",SUMIFS(Data!$W$4:$W$64,Data!$U$4:$U$64,2022,Data!$V$4:$V$64,2)) -> -0.029532354 | D60: =IF(COUNTIFS(Data!$U$4:$U$64,2022,Data!$V$4:$V$64,3)=0,"",SUMIFS(Data!$W$4:$W$64,Data!$U$4:$U$64,2022,Data!$V$4:$V$64,3)) -> 0.10884152 | E60: =IF(COUNTIFS(Data!$U$4:$U$64,2022,Data!$V$4:$V$64,4)=0,"",SUMIFS(Data!$W$4:$W$64,Data!$U$4:$U$64,2022,Data!$V$4:$V$64,4)) -> -0.021167155 | F60: =IF(COUNTIFS(Data!$U$4:$U$64,2022,Data!$V$4:$V$64,5)=0,"",SUMIFS(Data!$W$4:$W$64,Data!$U$4:$U$64,2022,Data!$V$4:$V$64,5)) -> -0.046541425 | G60: =IF(COUNTIFS(Data!$U$4:$U$64,2022,Data!$V$4:$V$64,6)=0,"",SUMIFS(Data!$W$4:$W$64,Data!$U$4:$U$64,2022,Data!$V$4:$V$64,6)) -> -0.065401015 | H60: =IF(COUNTIFS(Data!$U$4:$U$64,2022,Data!$V$4:$V$64,7)=0,"",SUMIFS(Data!$W$4:$W$64,Data!$U$4:$U$64,2022,Data!$V$4:$V$64,7)) -> 0.071264272 | I60: =IF(COUNTIFS(Data!$U$4:$U$64,2022,Data!$V$4:$V$64,8)=0,"",SUMIFS(Data!$W$4:$W$64,Data!$U$4:$U$64,2022,Data!$V$4:$V$64,8)) -> 0.067299623 | J60: =IF(COUNTIFS(Data!$U$4:$U$64,2022,Data!$V$4:$V$64,9)=0,"",SUMIFS(Data!$W$4:$W$64,Data!$U$4:$U$64,2022,Data!$V$4:$V$64,9)) -> 0.014397621 | K60: =IF(COUNTIFS(Data!$U$4:$U$64,2022,Data!$V$4:$V$64,10)=0,"",SUMIFS(Data!$W$4:$W$64,Data!$U$4:$U$64,2022,Data!$V$4:$V$64,10)) -> 0.012722327 | L60: =IF(COUNTIFS(Data!$U$4:$U$64,2022,Data!$V$4:$V$64,11)=0,"",SUMIFS(Data!$W$4:$W$64,Data!$U$4:$U$64,2022,Data!$V$4:$V$64,11)) -> 0.0046022394 | M60: =IF(COUNTIFS(Data!$U$4:$U$64,2022,Data!$V$4:$V$64,12)=0,"",SUMIFS(Data!$W$4:$W$64,Data!$U$4:$U$64,2022,Data!$V$4:$V$64,12)) -> -0.042758798 | N60: =INDEX(Data!$AC$4:$AC$9,MATCH(2022,Data!$AA$4:$AA$9,0)) -> 0.06169062 | O60: =INDEX(Data!$AD$4:$AD$9,MATCH(2022,Data!$AA$4:$AA$9,0)) -> 0.030184313 | P60: =INDEX(Data!$AE$4:$AE$9,MATCH(2022,Data!$AA$4:$AA$9,0)) -> 0.031506306
A61: 2023 | B61: =IF(COUNTIFS(Data!$U$4:$U$64,2023,Data!$V$4:$V$64,1)=0,"",SUMIFS(Data!$W$4:$W$64,Data!$U$4:$U$64,2023,Data!$V$4:$V$64,1)) -> -0.024490579 | C61: =IF(COUNTIFS(Data!$U$4:$U$64,2023,Data!$V$4:$V$64,2)=0,"",SUMIFS(Data!$W$4:$W$64,Data!$U$4:$U$64,2023,Data!$V$4:$V$64,2)) -> -0.0050317282 | D61: =IF(COUNTIFS(Data!$U$4:$U$64,2023,Data!$V$4:$V$64,3)=0,"",SUMIFS(Data!$W$4:$W$64,Data!$U$4:$U$64,2023,Data!$V$4:$V$64,3)) -> -0.011204118 | E61: =IF(COUNTIFS(Data!$U$4:$U$64,2023,Data!$V$4:$V$64,4)=0,"",SUMIFS(Data!$W$4:$W$64,Data!$U$4:$U$64,2023,Data!$V$4:$V$64,4)) -> 0.045855692 | F61: =IF(COUNTIFS(Data!$U$4:$U$64,2023,Data!$V$4:$V$64,5)=0,"",SUMIFS(Data!$W$4:$W$64,Data!$U$4:$U$64,2023,Data!$V$4:$V$64,5)) -> 0.034457254 | G61: =IF(COUNTIFS(Data!$U$4:$U$64,2023,Data!$V$4:$V$64,6)=0,"",SUMIFS(Data!$W$4:$W$64,Data!$U$4:$U$64,2023,Data!$V$4:$V$64,6)) -> 0.04995296 | H61: =IF(COUNTIFS(Data!$U$4:$U$64,2023,Data!$V$4:$V$64,7)=0,"",SUMIFS(Data!$W$4:$W$64,Data!$U$4:$U$64,2023,Data!$V$4:$V$64,7)) -> 0.087975714 | I61: =IF(COUNTIFS(Data!$U$4:$U$64,2023,Data!$V$4:$V$64,8)=0,"",SUMIFS(Data!$W$4:$W$64,Data!$U$4:$U$64,2023,Data!$V$4:$V$64,8)) -> 0.021907845 | J61: =IF(COUNTIFS(Data!$U$4:$U$64,2023,Data!$V$4:$V$64,9)=0,"",SUMIFS(Data!$W$4:$W$64,Data!$U$4:$U$64,2023,Data!$V$4:$V$64,9)) -> -0.0066212008 | K61: =IF(COUNTIFS(Data!$U$4:$U$64,2023,Data!$V$4:$V$64,10)=0,"",SUMIFS(Data!$W$4:$W$64,Data!$U$4:$U$64,2023,Data!$V$4:$V$64,10)) -> -0.0095014938 | L61: =IF(COUNTIFS(Data!$U$4:$U$64,2023,Data!$V$4:$V$64,11)=0,"",SUMIFS(Data!$W$4:$W$64,Data!$U$4:$U$64,2023,Data!$V$4:$V$64,11)) -> 0.11268064 | M61: =IF(COUNTIFS(Data!$U$4:$U$64,2023,Data!$V$4:$V$64,12)=0,"",SUMIFS(Data!$W$4:$W$64,Data!$U$4:$U$64,2023,Data!$V$4:$V$64,12)) -> 0.060353799 | N61: =INDEX(Data!$AC$4:$AC$9,MATCH(2023,Data!$AA$4:$AA$9,0)) -> 0.40709195 | O61: =INDEX(Data!$AD$4:$AD$9,MATCH(2023,Data!$AA$4:$AA$9,0)) -> 0.25764377 | P61: =INDEX(Data!$AE$4:$AE$9,MATCH(2023,Data!$AA$4:$AA$9,0)) -> 0.14944818
A62: 2024 | B62: =IF(COUNTIFS(Data!$U$4:$U$64,2024,Data!$V$4:$V$64,1)=0,"",SUMIFS(Data!$W$4:$W$64,Data!$U$4:$U$64,2024,Data!$V$4:$V$64,1)) -> 0.047025805 | C62: =IF(COUNTIFS(Data!$U$4:$U$64,2024,Data!$V$4:$V$64,2)=0,"",SUMIFS(Data!$W$4:$W$64,Data!$U$4:$U$64,2024,Data!$V$4:$V$64,2)) -> 0.018870931 | D62: =IF(COUNTIFS(Data!$U$4:$U$64,2024,Data!$V$4:$V$64,3)=0,"",SUMIFS(Data!$W$4:$W$64,Data!$U$4:$U$64,2024,Data!$V$4:$V$64,3)) -> 0.0065503435 | E62: =IF(COUNTIFS(Data!$U$4:$U$64,2024,Data!$V$4:$V$64,4)=0,"",SUMIFS(Data!$W$4:$W$64,Data!$U$4:$U$64,2024,Data!$V$4:$V$64,4)) -> 0.041310772 | F62: =IF(COUNTIFS(Data!$U$4:$U$64,2024,Data!$V$4:$V$64,5)=0,"",SUMIFS(Data!$W$4:$W$64,Data!$U$4:$U$64,2024,Data!$V$4:$V$64,5)) -> 0.04875291 | G62: =IF(COUNTIFS(Data!$U$4:$U$64,2024,Data!$V$4:$V$64,6)=0,"",SUMIFS(Data!$W$4:$W$64,Data!$U$4:$U$64,2024,Data!$V$4:$V$64,6)) -> 0.086965371 | H62: =IF(COUNTIFS(Data!$U$4:$U$64,2024,Data!$V$4:$V$64,7)=0,"",SUMIFS(Data!$W$4:$W$64,Data!$U$4:$U$64,2024,Data!$V$4:$V$64,7)) -> 0.060782482 | I62: =IF(COUNTIFS(Data!$U$4:$U$64,2024,Data!$V$4:$V$64,8)=0,"",SUMIFS(Data!$W$4:$W$64,Data!$U$4:$U$64,2024,Data!$V$4:$V$64,8)) -> -0.0096241418 | J62: =IF(COUNTIFS(Data!$U$4:$U$64,2024,Data!$V$4:$V$64,9)=0,"",SUMIFS(Data!$W$4:$W$64,Data!$U$4:$U$64,2024,Data!$V$4:$V$64,9)) -> 0.0014984637 | K62: =IF(COUNTIFS(Data!$U$4:$U$64,2024,Data!$V$4:$V$64,10)=0,"",SUMIFS(Data!$W$4:$W$64,Data!$U$4:$U$64,2024,Data!$V$4:$V$64,10)) -> -0.041877595 | L62: =IF(COUNTIFS(Data!$U$4:$U$64,2024,Data!$V$4:$V$64,11)=0,"",SUMIFS(Data!$W$4:$W$64,Data!$U$4:$U$64,2024,Data!$V$4:$V$64,11)) -> 0.010715634 | M62: =IF(COUNTIFS(Data!$U$4:$U$64,2024,Data!$V$4:$V$64,12)=0,"",SUMIFS(Data!$W$4:$W$64,Data!$U$4:$U$64,2024,Data!$V$4:$V$64,12)) -> -0.012120748 | N62: =INDEX(Data!$AC$4:$AC$9,MATCH(2024,Data!$AA$4:$AA$9,0)) -> 0.28295618 | O62: =INDEX(Data!$AD$4:$AD$9,MATCH(2024,Data!$AA$4:$AA$9,0)) -> 0.1516407 | P62: =INDEX(Data!$AE$4:$AE$9,MATCH(2024,Data!$AA$4:$AA$9,0)) -> 0.13131547
A63: 2025 | B63: =IF(COUNTIFS(Data!$U$4:$U$64,2025,Data!$V$4:$V$64,1)=0,"",SUMIFS(Data!$W$4:$W$64,Data!$U$4:$U$64,2025,Data!$V$4:$V$64,1)) -> -0.080404479 | C63: =IF(COUNTIFS(Data!$U$4:$U$64,2025,Data!$V$4:$V$64,2)=0,"",SUMIFS(Data!$W$4:$W$64,Data!$U$4:$U$64,2025,Data!$V$4:$V$64,2)) -> -0.11975303 | D63: =IF(COUNTIFS(Data!$U$4:$U$64,2025,Data!$V$4:$V$64,3)=0,"",SUMIFS(Data!$W$4:$W$64,Data!$U$4:$U$64,2025,Data!$V$4:$V$64,3)) -> 0.082520934 | E63: =IF(COUNTIFS(Data!$U$4:$U$64,2025,Data!$V$4:$V$64,4)=0,"",SUMIFS(Data!$W$4:$W$64,Data!$U$4:$U$64,2025,Data!$V$4:$V$64,4)) -> 0.020443284 | F63: =IF(COUNTIFS(Data!$U$4:$U$64,2025,Data!$V$4:$V$64,5)=0,"",SUMIFS(Data!$W$4:$W$64,Data!$U$4:$U$64,2025,Data!$V$4:$V$64,5)) -> 0.035162618 | G63: =IF(COUNTIFS(Data!$U$4:$U$64,2025,Data!$V$4:$V$64,6)=0,"",SUMIFS(Data!$W$4:$W$64,Data!$U$4:$U$64,2025,Data!$V$4:$V$64,6)) -> 0.034072807 | H63: =IF(COUNTIFS(Data!$U$4:$U$64,2025,Data!$V$4:$V$64,7)=0,"",SUMIFS(Data!$W$4:$W$64,Data!$U$4:$U$64,2025,Data!$V$4:$V$64,7)) -> 0.0014951721 | I63: =IF(COUNTIFS(Data!$U$4:$U$64,2025,Data!$V$4:$V$64,8)=0,"",SUMIFS(Data!$W$4:$W$64,Data!$U$4:$U$64,2025,Data!$V$4:$V$64,8)) -> 0.00038051484 | J63: =IF(COUNTIFS(Data!$U$4:$U$64,2025,Data!$V$4:$V$64,9)=0,"",SUMIFS(Data!$W$4:$W$64,Data!$U$4:$U$64,2025,Data!$V$4:$V$64,9)) -> -0.0095487009 | K63: =IF(COUNTIFS(Data!$U$4:$U$64,2025,Data!$V$4:$V$64,10)=0,"",SUMIFS(Data!$W$4:$W$64,Data!$U$4:$U$64,2025,Data!$V$4:$V$64,10)) -> 0.038607839 | L63: =IF(COUNTIFS(Data!$U$4:$U$64,2025,Data!$V$4:$V$64,11)=0,"",SUMIFS(Data!$W$4:$W$64,Data!$U$4:$U$64,2025,Data!$V$4:$V$64,11)) -> -0.03867425 | M63: =IF(COUNTIFS(Data!$U$4:$U$64,2025,Data!$V$4:$V$64,12)=0,"",SUMIFS(Data!$W$4:$W$64,Data!$U$4:$U$64,2025,Data!$V$4:$V$64,12)) -> 0.022677067 | N63: =INDEX(Data!$AC$4:$AC$9,MATCH(2025,Data!$AA$4:$AA$9,0)) -> -0.030173256 | O63: =INDEX(Data!$AD$4:$AD$9,MATCH(2025,Data!$AA$4:$AA$9,0)) -> 0.066865844 | P63: =INDEX(Data!$AE$4:$AE$9,MATCH(2025,Data!$AA$4:$AA$9,0)) -> -0.0970391
A64: 2026 | B64: =IF(COUNTIFS(Data!$U$4:$U$64,2026,Data!$V$4:$V$64,1)=0,"",SUMIFS(Data!$W$4:$W$64,Data!$U$4:$U$64,2026,Data!$V$4:$V$64,1)) -> -0.012001884 | C64: =IF(COUNTIFS(Data!$U$4:$U$64,2026,Data!$V$4:$V$64,2)=0,"",SUMIFS(Data!$W$4:$W$64,Data!$U$4:$U$64,2026,Data!$V$4:$V$64,2)) -> -0.015040304 | D64: =IF(COUNTIFS(Data!$U$4:$U$64,2026,Data!$V$4:$V$64,3)=0,"",SUMIFS(Data!$W$4:$W$64,Data!$U$4:$U$64,2026,Data!$V$4:$V$64,3)) -> -0.095831925 | E64: =IF(COUNTIFS(Data!$U$4:$U$64,2026,Data!$V$4:$V$64,4)=0,"",SUMIFS(Data!$W$4:$W$64,Data!$U$4:$U$64,2026,Data!$V$4:$V$64,4)) -> 0.13566435 | F64: =IF(COUNTIFS(Data!$U$4:$U$64,2026,Data!$V$4:$V$64,5)=0,"",SUMIFS(Data!$W$4:$W$64,Data!$U$4:$U$64,2026,Data!$V$4:$V$64,5)) -> 0.052378408 | G64: =IF(COUNTIFS(Data!$U$4:$U$64,2026,Data!$V$4:$V$64,6)=0,"",SUMIFS(Data!$W$4:$W$64,Data!$U$4:$U$64,2026,Data!$V$4:$V$64,6)) -> 0.022839787 | H64: =IF(COUNTIFS(Data!$U$4:$U$64,2026,Data!$V$4:$V$64,7)=0,"",SUMIFS(Data!$W$4:$W$64,Data!$U$4:$U$64,2026,Data!$V$4:$V$64,7)) -> 0.024671045 | I64: =IF(COUNTIFS(Data!$U$4:$U$64,2026,Data!$V$4:$V$64,8)=0,"",SUMIFS(Data!$W$4:$W$64,Data!$U$4:$U$64,2026,Data!$V$4:$V$64,8)) -> 0.0051722537 | J64: =IF(COUNTIFS(Data!$U$4:$U$64,2026,Data!$V$4:$V$64,9)=0,"",SUMIFS(Data!$W$4:$W$64,Data!$U$4:$U$64,2026,Data!$V$4:$V$64,9)) | K64: =IF(COUNTIFS(Data!$U$4:$U$64,2026,Data!$V$4:$V$64,10)=0,"",SUMIFS(Data!$W$4:$W$64,Data!$U$4:$U$64,2026,Data!$V$4:$V$64,10)) | L64: =IF(COUNTIFS(Data!$U$4:$U$64,2026,Data!$V$4:$V$64,11)=0,"",SUMIFS(Data!$W$4:$W$64,Data!$U$4:$U$64,2026,Data!$V$4:$V$64,11)) | M64: =IF(COUNTIFS(Data!$U$4:$U$64,2026,Data!$V$4:$V$64,12)=0,"",SUMIFS(Data!$W$4:$W$64,Data!$U$4:$U$64,2026,Data!$V$4:$V$64,12)) | N64: =INDEX(Data!$AC$4:$AC$9,MATCH(2026,Data!$AA$4:$AA$9,0)) -> 0.10784304 | O64: =INDEX(Data!$AD$4:$AD$9,MATCH(2026,Data!$AA$4:$AA$9,0)) -> -0.0079760217 | P64: =INDEX(Data!$AE$4:$AE$9,MATCH(2026,Data!$AA$4:$AA$9,0)) -> 0.11581907
A65: Month avg | B65: =IFERROR(AVERAGE(B59:B64),"") -> -0.013690964 | C65: =IFERROR(AVERAGE(C59:C64),"") -> -0.030097298 | D65: =IFERROR(AVERAGE(D59:D64),"") -> 0.01817535 | E65: =IFERROR(AVERAGE(E59:E64),"") -> 0.044421388 | F65: =IFERROR(AVERAGE(F59:F64),"") -> 0.024841953 | G65: =IFERROR(AVERAGE(G59:G64),"") -> 0.025685982 | H65: =IFERROR(AVERAGE(H59:H64),"") -> 0.049237737 | I65: =IFERROR(AVERAGE(I59:I64),"") -> 0.017183309 | ... M65: =IFERROR(AVERAGE(M59:M64),"") -> 0.01285975
A66: % positive | B66: =IFERROR(COUNTIF(B59:B64,">0")/COUNT(B59:B64),"") -> 0.4 | C66: =IFERROR(COUNTIF(C59:C64,">0")/COUNT(C59:C64),"") -> 0.2 | D66: =IFERROR(COUNTIF(D59:D64,">0")/COUNT(D59:D64),"") -> 0.6 | E66: =IFERROR(COUNTIF(E59:E64,">0")/COUNT(E59:E64),"") -> 0.8 | F66: =IFERROR(COUNTIF(F59:F64,">0")/COUNT(F59:F64),"") -> 0.8 | G66: =IFERROR(COUNTIF(G59:G64,">0")/COUNT(G59:G64),"") -> 0.8 | H66: =IFERROR(COUNTIF(H59:H64,">0")/COUNT(H59:H64),"") -> 1 | I66: =IFERROR(COUNTIF(I59:I64,">0")/COUNT(I59:I64),"") -> 0.83333333 | ... M66: =IFERROR(COUNTIF(M59:M64,">0")/COUNT(M59:M64),"") -> 0.6
A68: Monthly excess vs NIFTY 500 price index (YTD / Annual column = calendar-year excess)
A69: Year | B69: Jan | C69: Feb | D69: Mar | E69: Apr | F69: May | G69: Jun | H69: Jul | I69: Aug | J69: Sep | K69: Oct | L69: Nov | M69: Dec | N69: YTD / Annual | O69: NIFTY 500 | P69: Excess
A70: 2021 | B70: =IF(COUNTIFS(Data!$U$4:$U$64,2021,Data!$V$4:$V$64,1)=0,"",SUMIFS(Data!$Y$4:$Y$64,Data!$U$4:$U$64,2021,Data!$V$4:$V$64,1)) | C70: =IF(COUNTIFS(Data!$U$4:$U$64,2021,Data!$V$4:$V$64,2)=0,"",SUMIFS(Data!$Y$4:$Y$64,Data!$U$4:$U$64,2021,Data!$V$4:$V$64,2)) | D70: =IF(COUNTIFS(Data!$U$4:$U$64,2021,Data!$V$4:$V$64,3)=0,"",SUMIFS(Data!$Y$4:$Y$64,Data!$U$4:$U$64,2021,Data!$V$4:$V$64,3)) | E70: =IF(COUNTIFS(Data!$U$4:$U$64,2021,Data!$V$4:$V$64,4)=0,"",SUMIFS(Data!$Y$4:$Y$64,Data!$U$4:$U$64,2021,Data!$V$4:$V$64,4)) | F70: =IF(COUNTIFS(Data!$U$4:$U$64,2021,Data!$V$4:$V$64,5)=0,"",SUMIFS(Data!$Y$4:$Y$64,Data!$U$4:$U$64,2021,Data!$V$4:$V$64,5)) | G70: =IF(COUNTIFS(Data!$U$4:$U$64,2021,Data!$V$4:$V$64,6)=0,"",SUMIFS(Data!$Y$4:$Y$64,Data!$U$4:$U$64,2021,Data!$V$4:$V$64,6)) | H70: =IF(COUNTIFS(Data!$U$4:$U$64,2021,Data!$V$4:$V$64,7)=0,"",SUMIFS(Data!$Y$4:$Y$64,Data!$U$4:$U$64,2021,Data!$V$4:$V$64,7)) | I70: =IF(COUNTIFS(Data!$U$4:$U$64,2021,Data!$V$4:$V$64,8)=0,"",SUMIFS(Data!$Y$4:$Y$64,Data!$U$4:$U$64,2021,Data!$V$4:$V$64,8)) -> -0.030992935 | J70: =IF(COUNTIFS(Data!$U$4:$U$64,2021,Data!$V$4:$V$64,9)=0,"",SUMIFS(Data!$Y$4:$Y$64,Data!$U$4:$U$64,2021,Data!$V$4:$V$64,9)) -> -0.026266271 | K70: =IF(COUNTIFS(Data!$U$4:$U$64,2021,Data!$V$4:$V$64,10)=0,"",SUMIFS(Data!$Y$4:$Y$64,Data!$U$4:$U$64,2021,Data!$V$4:$V$64,10)) -> -0.026740445 | L70: =IF(COUNTIFS(Data!$U$4:$U$64,2021,Data!$V$4:$V$64,11)=0,"",SUMIFS(Data!$Y$4:$Y$64,Data!$U$4:$U$64,2021,Data!$V$4:$V$64,11)) -> 0.062438165 | M70: =IF(COUNTIFS(Data!$U$4:$U$64,2021,Data!$V$4:$V$64,12)=0,"",SUMIFS(Data!$Y$4:$Y$64,Data!$U$4:$U$64,2021,Data!$V$4:$V$64,12)) -> 0.012400729 | N70: =INDEX(Data!$AE$4:$AE$9,MATCH(2021,Data!$AA$4:$AA$9,0)) -> -0.0090363098 | O70: =INDEX(Data!$AD$4:$AD$9,MATCH(2021,Data!$AA$4:$AA$9,0)) -> 0.080686482 | P70: =INDEX(Data!$AE$4:$AE$9,MATCH(2021,Data!$AA$4:$AA$9,0)) -> -0.0090363098
A71: 2022 | B71: =IF(COUNTIFS(Data!$U$4:$U$64,2022,Data!$V$4:$V$64,1)=0,"",SUMIFS(Data!$Y$4:$Y$64,Data!$U$4:$U$64,2022,Data!$V$4:$V$64,1)) -> 0.0064009154 | C71: =IF(COUNTIFS(Data!$U$4:$U$64,2022,Data!$V$4:$V$64,2)=0,"",SUMIFS(Data!$Y$4:$Y$64,Data!$U$4:$U$64,2022,Data!$V$4:$V$64,2)) -> 0.011582953 | D71: =IF(COUNTIFS(Data!$U$4:$U$64,2022,Data!$V$4:$V$64,3)=0,"",SUMIFS(Data!$Y$4:$Y$64,Data!$U$4:$U$64,2022,Data!$V$4:$V$64,3)) -> 0.067846823 | E71: =IF(COUNTIFS(Data!$U$4:$U$64,2022,Data!$V$4:$V$64,4)=0,"",SUMIFS(Data!$Y$4:$Y$64,Data!$U$4:$U$64,2022,Data!$V$4:$V$64,4)) -> -0.013704669 | F71: =IF(COUNTIFS(Data!$U$4:$U$64,2022,Data!$V$4:$V$64,5)=0,"",SUMIFS(Data!$Y$4:$Y$64,Data!$U$4:$U$64,2022,Data!$V$4:$V$64,5)) -> -0.0016429408 | G71: =IF(COUNTIFS(Data!$U$4:$U$64,2022,Data!$V$4:$V$64,6)=0,"",SUMIFS(Data!$Y$4:$Y$64,Data!$U$4:$U$64,2022,Data!$V$4:$V$64,6)) -> -0.013554645 | H71: =IF(COUNTIFS(Data!$U$4:$U$64,2022,Data!$V$4:$V$64,7)=0,"",SUMIFS(Data!$Y$4:$Y$64,Data!$U$4:$U$64,2022,Data!$V$4:$V$64,7)) -> -0.024205026 | I71: =IF(COUNTIFS(Data!$U$4:$U$64,2022,Data!$V$4:$V$64,8)=0,"",SUMIFS(Data!$Y$4:$Y$64,Data!$U$4:$U$64,2022,Data!$V$4:$V$64,8)) -> 0.022337415 | J71: =IF(COUNTIFS(Data!$U$4:$U$64,2022,Data!$V$4:$V$64,9)=0,"",SUMIFS(Data!$Y$4:$Y$64,Data!$U$4:$U$64,2022,Data!$V$4:$V$64,9)) -> 0.046743356 | K71: =IF(COUNTIFS(Data!$U$4:$U$64,2022,Data!$V$4:$V$64,10)=0,"",SUMIFS(Data!$Y$4:$Y$64,Data!$U$4:$U$64,2022,Data!$V$4:$V$64,10)) -> -0.027377205 | L71: =IF(COUNTIFS(Data!$U$4:$U$64,2022,Data!$V$4:$V$64,11)=0,"",SUMIFS(Data!$Y$4:$Y$64,Data!$U$4:$U$64,2022,Data!$V$4:$V$64,11)) -> -0.029250847 | M71: =IF(COUNTIFS(Data!$U$4:$U$64,2022,Data!$V$4:$V$64,12)=0,"",SUMIFS(Data!$Y$4:$Y$64,Data!$U$4:$U$64,2022,Data!$V$4:$V$64,12)) -> -0.011572587 | N71: =INDEX(Data!$AE$4:$AE$9,MATCH(2022,Data!$AA$4:$AA$9,0)) -> 0.031506306 | O71: =INDEX(Data!$AD$4:$AD$9,MATCH(2022,Data!$AA$4:$AA$9,0)) -> 0.030184313 | P71: =INDEX(Data!$AE$4:$AE$9,MATCH(2022,Data!$AA$4:$AA$9,0)) -> 0.031506306
A72: 2023 | B72: =IF(COUNTIFS(Data!$U$4:$U$64,2023,Data!$V$4:$V$64,1)=0,"",SUMIFS(Data!$Y$4:$Y$64,Data!$U$4:$U$64,2023,Data!$V$4:$V$64,1)) -> 0.0087384317 | C72: =IF(COUNTIFS(Data!$U$4:$U$64,2023,Data!$V$4:$V$64,2)=0,"",SUMIFS(Data!$Y$4:$Y$64,Data!$U$4:$U$64,2023,Data!$V$4:$V$64,2)) -> 0.022871589 | D72: =IF(COUNTIFS(Data!$U$4:$U$64,2023,Data!$V$4:$V$64,3)=0,"",SUMIFS(Data!$Y$4:$Y$64,Data!$U$4:$U$64,2023,Data!$V$4:$V$64,3)) -> -0.013897188 | E72: =IF(COUNTIFS(Data!$U$4:$U$64,2023,Data!$V$4:$V$64,4)=0,"",SUMIFS(Data!$Y$4:$Y$64,Data!$U$4:$U$64,2023,Data!$V$4:$V$64,4)) -> 0.0004025516 | F72: =IF(COUNTIFS(Data!$U$4:$U$64,2023,Data!$V$4:$V$64,5)=0,"",SUMIFS(Data!$Y$4:$Y$64,Data!$U$4:$U$64,2023,Data!$V$4:$V$64,5)) -> -0.0014735056 | G72: =IF(COUNTIFS(Data!$U$4:$U$64,2023,Data!$V$4:$V$64,6)=0,"",SUMIFS(Data!$Y$4:$Y$64,Data!$U$4:$U$64,2023,Data!$V$4:$V$64,6)) -> 0.0078634533 | H72: =IF(COUNTIFS(Data!$U$4:$U$64,2023,Data!$V$4:$V$64,7)=0,"",SUMIFS(Data!$Y$4:$Y$64,Data!$U$4:$U$64,2023,Data!$V$4:$V$64,7)) -> 0.049692086 | I72: =IF(COUNTIFS(Data!$U$4:$U$64,2023,Data!$V$4:$V$64,8)=0,"",SUMIFS(Data!$Y$4:$Y$64,Data!$U$4:$U$64,2023,Data!$V$4:$V$64,8)) -> 0.02980397 | J72: =IF(COUNTIFS(Data!$U$4:$U$64,2023,Data!$V$4:$V$64,9)=0,"",SUMIFS(Data!$Y$4:$Y$64,Data!$U$4:$U$64,2023,Data!$V$4:$V$64,9)) -> -0.02838281 | K72: =IF(COUNTIFS(Data!$U$4:$U$64,2023,Data!$V$4:$V$64,10)=0,"",SUMIFS(Data!$Y$4:$Y$64,Data!$U$4:$U$64,2023,Data!$V$4:$V$64,10)) -> 0.018921068 | L72: =IF(COUNTIFS(Data!$U$4:$U$64,2023,Data!$V$4:$V$64,11)=0,"",SUMIFS(Data!$Y$4:$Y$64,Data!$U$4:$U$64,2023,Data!$V$4:$V$64,11)) -> 0.042039434 | M72: =IF(COUNTIFS(Data!$U$4:$U$64,2023,Data!$V$4:$V$64,12)=0,"",SUMIFS(Data!$Y$4:$Y$64,Data!$U$4:$U$64,2023,Data!$V$4:$V$64,12)) -> -0.019766504 | N72: =INDEX(Data!$AE$4:$AE$9,MATCH(2023,Data!$AA$4:$AA$9,0)) -> 0.14944818 | O72: =INDEX(Data!$AD$4:$AD$9,MATCH(2023,Data!$AA$4:$AA$9,0)) -> 0.25764377 | P72: =INDEX(Data!$AE$4:$AE$9,MATCH(2023,Data!$AA$4:$AA$9,0)) -> 0.14944818
A73: 2024 | B73: =IF(COUNTIFS(Data!$U$4:$U$64,2024,Data!$V$4:$V$64,1)=0,"",SUMIFS(Data!$Y$4:$Y$64,Data!$U$4:$U$64,2024,Data!$V$4:$V$64,1)) -> 0.027830421 | C73: =IF(COUNTIFS(Data!$U$4:$U$64,2024,Data!$V$4:$V$64,2)=0,"",SUMIFS(Data!$Y$4:$Y$64,Data!$U$4:$U$64,2024,Data!$V$4:$V$64,2)) -> 0.0043295443 | D73: =IF(COUNTIFS(Data!$U$4:$U$64,2024,Data!$V$4:$V$64,3)=0,"",SUMIFS(Data!$Y$4:$Y$64,Data!$U$4:$U$64,2024,Data!$V$4:$V$64,3)) -> -0.0016676549 | E73: =IF(COUNTIFS(Data!$U$4:$U$64,2024,Data!$V$4:$V$64,4)=0,"",SUMIFS(Data!$Y$4:$Y$64,Data!$U$4:$U$64,2024,Data!$V$4:$V$64,4)) -> 0.0046756444 | F73: =IF(COUNTIFS(Data!$U$4:$U$64,2024,Data!$V$4:$V$64,5)=0,"",SUMIFS(Data!$Y$4:$Y$64,Data!$U$4:$U$64,2024,Data!$V$4:$V$64,5)) -> 0.043699855 | G73: =IF(COUNTIFS(Data!$U$4:$U$64,2024,Data!$V$4:$V$64,6)=0,"",SUMIFS(Data!$Y$4:$Y$64,Data!$U$4:$U$64,2024,Data!$V$4:$V$64,6)) -> 0.017952468 | H73: =IF(COUNTIFS(Data!$U$4:$U$64,2024,Data!$V$4:$V$64,7)=0,"",SUMIFS(Data!$Y$4:$Y$64,Data!$U$4:$U$64,2024,Data!$V$4:$V$64,7)) -> 0.017736697 | I73: =IF(COUNTIFS(Data!$U$4:$U$64,2024,Data!$V$4:$V$64,8)=0,"",SUMIFS(Data!$Y$4:$Y$64,Data!$U$4:$U$64,2024,Data!$V$4:$V$64,8)) -> -0.018283006 | J73: =IF(COUNTIFS(Data!$U$4:$U$64,2024,Data!$V$4:$V$64,9)=0,"",SUMIFS(Data!$Y$4:$Y$64,Data!$U$4:$U$64,2024,Data!$V$4:$V$64,9)) -> -0.020016585 | K73: =IF(COUNTIFS(Data!$U$4:$U$64,2024,Data!$V$4:$V$64,10)=0,"",SUMIFS(Data!$Y$4:$Y$64,Data!$U$4:$U$64,2024,Data!$V$4:$V$64,10)) -> 0.02229387 | L73: =IF(COUNTIFS(Data!$U$4:$U$64,2024,Data!$V$4:$V$64,11)=0,"",SUMIFS(Data!$Y$4:$Y$64,Data!$U$4:$U$64,2024,Data!$V$4:$V$64,11)) -> 0.010819207 | M73: =IF(COUNTIFS(Data!$U$4:$U$64,2024,Data!$V$4:$V$64,12)=0,"",SUMIFS(Data!$Y$4:$Y$64,Data!$U$4:$U$64,2024,Data!$V$4:$V$64,12)) -> 0.0016139898 | N73: =INDEX(Data!$AE$4:$AE$9,MATCH(2024,Data!$AA$4:$AA$9,0)) -> 0.13131547 | O73: =INDEX(Data!$AD$4:$AD$9,MATCH(2024,Data!$AA$4:$AA$9,0)) -> 0.1516407 | P73: =INDEX(Data!$AE$4:$AE$9,MATCH(2024,Data!$AA$4:$AA$9,0)) -> 0.13131547
A74: 2025 | B74: =IF(COUNTIFS(Data!$U$4:$U$64,2025,Data!$V$4:$V$64,1)=0,"",SUMIFS(Data!$Y$4:$Y$64,Data!$U$4:$U$64,2025,Data!$V$4:$V$64,1)) -> -0.044896734 | C74: =IF(COUNTIFS(Data!$U$4:$U$64,2025,Data!$V$4:$V$64,2)=0,"",SUMIFS(Data!$Y$4:$Y$64,Data!$U$4:$U$64,2025,Data!$V$4:$V$64,2)) -> -0.040979675 | D74: =IF(COUNTIFS(Data!$U$4:$U$64,2025,Data!$V$4:$V$64,3)=0,"",SUMIFS(Data!$Y$4:$Y$64,Data!$U$4:$U$64,2025,Data!$V$4:$V$64,3)) -> 0.0091515191 | E74: =IF(COUNTIFS(Data!$U$4:$U$64,2025,Data!$V$4:$V$64,4)=0,"",SUMIFS(Data!$Y$4:$Y$64,Data!$U$4:$U$64,2025,Data!$V$4:$V$64,4)) -> -0.011914474 | F74: =IF(COUNTIFS(Data!$U$4:$U$64,2025,Data!$V$4:$V$64,5)=0,"",SUMIFS(Data!$Y$4:$Y$64,Data!$U$4:$U$64,2025,Data!$V$4:$V$64,5)) -> 0.00012411407 | G74: =IF(COUNTIFS(Data!$U$4:$U$64,2025,Data!$V$4:$V$64,6)=0,"",SUMIFS(Data!$Y$4:$Y$64,Data!$U$4:$U$64,2025,Data!$V$4:$V$64,6)) -> -0.0016807137 | H74: =IF(COUNTIFS(Data!$U$4:$U$64,2025,Data!$V$4:$V$64,7)=0,"",SUMIFS(Data!$Y$4:$Y$64,Data!$U$4:$U$64,2025,Data!$V$4:$V$64,7)) -> 0.031229857 | I74: =IF(COUNTIFS(Data!$U$4:$U$64,2025,Data!$V$4:$V$64,8)=0,"",SUMIFS(Data!$Y$4:$Y$64,Data!$U$4:$U$64,2025,Data!$V$4:$V$64,8)) -> 0.020105629 | J74: =IF(COUNTIFS(Data!$U$4:$U$64,2025,Data!$V$4:$V$64,9)=0,"",SUMIFS(Data!$Y$4:$Y$64,Data!$U$4:$U$64,2025,Data!$V$4:$V$64,9)) -> -0.021619689 | K74: =IF(COUNTIFS(Data!$U$4:$U$64,2025,Data!$V$4:$V$64,10)=0,"",SUMIFS(Data!$Y$4:$Y$64,Data!$U$4:$U$64,2025,Data!$V$4:$V$64,10)) -> -0.0043364605 | L74: =IF(COUNTIFS(Data!$U$4:$U$64,2025,Data!$V$4:$V$64,11)=0,"",SUMIFS(Data!$Y$4:$Y$64,Data!$U$4:$U$64,2025,Data!$V$4:$V$64,11)) -> -0.04807097 | M74: =IF(COUNTIFS(Data!$U$4:$U$64,2025,Data!$V$4:$V$64,12)=0,"",SUMIFS(Data!$Y$4:$Y$64,Data!$U$4:$U$64,2025,Data!$V$4:$V$64,12)) -> 0.025252986 | N74: =INDEX(Data!$AE$4:$AE$9,MATCH(2025,Data!$AA$4:$AA$9,0)) -> -0.0970391 | O74: =INDEX(Data!$AD$4:$AD$9,MATCH(2025,Data!$AA$4:$AA$9,0)) -> 0.066865844 | P74: =INDEX(Data!$AE$4:$AE$9,MATCH(2025,Data!$AA$4:$AA$9,0)) -> -0.0970391
A75: 2026 | B75: =IF(COUNTIFS(Data!$U$4:$U$64,2026,Data!$V$4:$V$64,1)=0,"",SUMIFS(Data!$Y$4:$Y$64,Data!$U$4:$U$64,2026,Data!$V$4:$V$64,1)) -> 0.02117778 | C75: =IF(COUNTIFS(Data!$U$4:$U$64,2026,Data!$V$4:$V$64,2)=0,"",SUMIFS(Data!$Y$4:$Y$64,Data!$U$4:$U$64,2026,Data!$V$4:$V$64,2)) -> -0.018825048 | D75: =IF(COUNTIFS(Data!$U$4:$U$64,2026,Data!$V$4:$V$64,3)=0,"",SUMIFS(Data!$Y$4:$Y$64,Data!$U$4:$U$64,2026,Data!$V$4:$V$64,3)) -> 0.018072209 | E75: =IF(COUNTIFS(Data!$U$4:$U$64,2026,Data!$V$4:$V$64,4)=0,"",SUMIFS(Data!$Y$4:$Y$64,Data!$U$4:$U$64,2026,Data!$V$4:$V$64,4)) -> 0.030661682 | F75: =IF(COUNTIFS(Data!$U$4:$U$64,2026,Data!$V$4:$V$64,5)=0,"",SUMIFS(Data!$Y$4:$Y$64,Data!$U$4:$U$64,2026,Data!$V$4:$V$64,5)) -> 0.053548859 | G75: =IF(COUNTIFS(Data!$U$4:$U$64,2026,Data!$V$4:$V$64,6)=0,"",SUMIFS(Data!$Y$4:$Y$64,Data!$U$4:$U$64,2026,Data!$V$4:$V$64,6)) -> 0.007892971 | H75: =IF(COUNTIFS(Data!$U$4:$U$64,2026,Data!$V$4:$V$64,7)=0,"",SUMIFS(Data!$Y$4:$Y$64,Data!$U$4:$U$64,2026,Data!$V$4:$V$64,7)) -> 0.0044476546 | I75: =IF(COUNTIFS(Data!$U$4:$U$64,2026,Data!$V$4:$V$64,8)=0,"",SUMIFS(Data!$Y$4:$Y$64,Data!$U$4:$U$64,2026,Data!$V$4:$V$64,8)) -> -0.0042243117 | J75: =IF(COUNTIFS(Data!$U$4:$U$64,2026,Data!$V$4:$V$64,9)=0,"",SUMIFS(Data!$Y$4:$Y$64,Data!$U$4:$U$64,2026,Data!$V$4:$V$64,9)) | K75: =IF(COUNTIFS(Data!$U$4:$U$64,2026,Data!$V$4:$V$64,10)=0,"",SUMIFS(Data!$Y$4:$Y$64,Data!$U$4:$U$64,2026,Data!$V$4:$V$64,10)) | L75: =IF(COUNTIFS(Data!$U$4:$U$64,2026,Data!$V$4:$V$64,11)=0,"",SUMIFS(Data!$Y$4:$Y$64,Data!$U$4:$U$64,2026,Data!$V$4:$V$64,11)) | M75: =IF(COUNTIFS(Data!$U$4:$U$64,2026,Data!$V$4:$V$64,12)=0,"",SUMIFS(Data!$Y$4:$Y$64,Data!$U$4:$U$64,2026,Data!$V$4:$V$64,12)) | N75: =INDEX(Data!$AE$4:$AE$9,MATCH(2026,Data!$AA$4:$AA$9,0)) -> 0.11581907 | O75: =INDEX(Data!$AD$4:$AD$9,MATCH(2026,Data!$AA$4:$AA$9,0)) -> -0.0079760217 | P75: =INDEX(Data!$AE$4:$AE$9,MATCH(2026,Data!$AA$4:$AA$9,0)) -> 0.11581907
A76: Month avg | B76: =IFERROR(AVERAGE(B70:B75),"") -> 0.0038501627 | C76: =IFERROR(AVERAGE(C70:C75),"") -> -0.0042041273 | D76: =IFERROR(AVERAGE(D70:D75),"") -> 0.015901142 | E76: =IFERROR(AVERAGE(E70:E75),"") -> 0.0020241469 | F76: =IFERROR(AVERAGE(F70:F75),"") -> 0.018851276 | G76: =IFERROR(AVERAGE(G70:G75),"") -> 0.0036947067 | H76: =IFERROR(AVERAGE(H70:H75),"") -> 0.015780254 | I76: =IFERROR(AVERAGE(I70:I75),"") -> 0.0031244602 | ... M76: =IFERROR(AVERAGE(M70:M75),"") -> 0.0015857229
A77: % positive | B77: =IFERROR(COUNTIF(B70:B75,">0")/COUNT(B70:B75),"") -> 0.8 | C77: =IFERROR(COUNTIF(C70:C75,">0")/COUNT(C70:C75),"") -> 0.6 | D77: =IFERROR(COUNTIF(D70:D75,">0")/COUNT(D70:D75),"") -> 0.6 | E77: =IFERROR(COUNTIF(E70:E75,">0")/COUNT(E70:E75),"") -> 0.6 | F77: =IFERROR(COUNTIF(F70:F75,">0")/COUNT(F70:F75),"") -> 0.6 | G77: =IFERROR(COUNTIF(G70:G75,">0")/COUNT(G70:G75),"") -> 0.6 | H77: =IFERROR(COUNTIF(H70:H75,">0")/COUNT(H70:H75),"") -> 0.8 | I77: =IFERROR(COUNTIF(I70:I75,">0")/COUNT(I70:I75),"") -> 0.5 | ... M77: =IFERROR(COUNTIF(M70:M75,">0")/COUNT(M70:M75),"") -> 0.6
A80: 5 · Trade-level net return distribution — strategy vs placebo (random books, same mechanics)
A81: Bin (net return) | B81: Lower | C81: Upper | D81: Strategy (% of trades) | E81: Placebo (% of trades)
A82: < -40% | B82: -9.99 | C82: -0.4 | D82: =COUNTIFS('Trade Log'!$O$5:$O$571,">="&B82,'Trade Log'!$O$5:$O$571,"<"&C82)/COUNT('Trade Log'!$O$5:$O$571) -> 0.0035273369 | E82: =COUNTIFS(Data!$BI$4:$BI$23245,">="&B82,Data!$BI$4:$BI$23245,"<"&C82)/COUNT(Data!$BI$4:$BI$23245) -> 0.0027106101
A83: -40% to -35% | B83: -0.4 | C83: -0.35 | D83: =COUNTIFS('Trade Log'!$O$5:$O$571,">="&B83,'Trade Log'!$O$5:$O$571,"<"&C83)/COUNT('Trade Log'!$O$5:$O$571) -> 0.0017636684 | E83: =COUNTIFS(Data!$BI$4:$BI$23245,">="&B83,Data!$BI$4:$BI$23245,"<"&C83)/COUNT(Data!$BI$4:$BI$23245) -> 0.0011186645
A84: -35% to -30% | B84: -0.35 | C84: -0.3 | D84: =COUNTIFS('Trade Log'!$O$5:$O$571,">="&B84,'Trade Log'!$O$5:$O$571,"<"&C84)/COUNT('Trade Log'!$O$5:$O$571) -> 0.0035273369 | E84: =COUNTIFS(Data!$BI$4:$BI$23245,">="&B84,Data!$BI$4:$BI$23245,"<"&C84)/COUNT(Data!$BI$4:$BI$23245) -> 0.0061526547
A85: -30% to -25% | B85: -0.3 | C85: -0.25 | D85: =COUNTIFS('Trade Log'!$O$5:$O$571,">="&B85,'Trade Log'!$O$5:$O$571,"<"&C85)/COUNT('Trade Log'!$O$5:$O$571) -> 0.010582011 | E85: =COUNTIFS(Data!$BI$4:$BI$23245,">="&B85,Data!$BI$4:$BI$23245,"<"&C85)/COUNT(Data!$BI$4:$BI$23245) -> 0.0092074692
A86: -25% to -20% | B86: -0.25 | C86: -0.2 | D86: =COUNTIFS('Trade Log'!$O$5:$O$571,">="&B86,'Trade Log'!$O$5:$O$571,"<"&C86)/COUNT('Trade Log'!$O$5:$O$571) -> 0.0335097 | E86: =COUNTIFS(Data!$BI$4:$BI$23245,">="&B86,Data!$BI$4:$BI$23245,"<"&C86)/COUNT(Data!$BI$4:$BI$23245) -> 0.025987437
A87: -20% to -15% | B87: -0.2 | C87: -0.15 | D87: =COUNTIFS('Trade Log'!$O$5:$O$571,">="&B87,'Trade Log'!$O$5:$O$571,"<"&C87)/COUNT('Trade Log'!$O$5:$O$571) -> 0.044091711 | E87: =COUNTIFS(Data!$BI$4:$BI$23245,">="&B87,Data!$BI$4:$BI$23245,"<"&C87)/COUNT(Data!$BI$4:$BI$23245) -> 0.059332243
A88: -15% to -10% | B88: -0.15 | C88: -0.1 | D88: =COUNTIFS('Trade Log'!$O$5:$O$571,">="&B88,'Trade Log'!$O$5:$O$571,"<"&C88)/COUNT('Trade Log'!$O$5:$O$571) -> 0.065255732 | E88: =COUNTIFS(Data!$BI$4:$BI$23245,">="&B88,Data!$BI$4:$BI$23245,"<"&C88)/COUNT(Data!$BI$4:$BI$23245) -> 0.089105929
A89: -10% to -5% | B89: -0.1 | C89: -0.05 | D89: =COUNTIFS('Trade Log'!$O$5:$O$571,">="&B89,'Trade Log'!$O$5:$O$571,"<"&C89)/COUNT('Trade Log'!$O$5:$O$571) -> 0.1340388 | E89: =COUNTIFS(Data!$BI$4:$BI$23245,">="&B89,Data!$BI$4:$BI$23245,"<"&C89)/COUNT(Data!$BI$4:$BI$23245) -> 0.13604681
A90: -5% to 0% | B90: -0.05 | C90: 0 | D90: =COUNTIFS('Trade Log'!$O$5:$O$571,">="&B90,'Trade Log'!$O$5:$O$571,"<"&C90)/COUNT('Trade Log'!$O$5:$O$571) -> 0.11992945 | E90: =COUNTIFS(Data!$BI$4:$BI$23245,">="&B90,Data!$BI$4:$BI$23245,"<"&C90)/COUNT(Data!$BI$4:$BI$23245) -> 0.14219947
A91: 0% to 5% | B91: 0 | C91: 0.05 | D91: =COUNTIFS('Trade Log'!$O$5:$O$571,">="&B91,'Trade Log'!$O$5:$O$571,"<"&C91)/COUNT('Trade Log'!$O$5:$O$571) -> 0.13051146 | E91: =COUNTIFS(Data!$BI$4:$BI$23245,">="&B91,Data!$BI$4:$BI$23245,"<"&C91)/COUNT(Data!$BI$4:$BI$23245) -> 0.13639102
A92: 5% to 10% | B92: 0.05 | C92: 0.1 | D92: =COUNTIFS('Trade Log'!$O$5:$O$571,">="&B92,'Trade Log'!$O$5:$O$571,"<"&C92)/COUNT('Trade Log'!$O$5:$O$571) -> 0.13756614 | E92: =COUNTIFS(Data!$BI$4:$BI$23245,">="&B92,Data!$BI$4:$BI$23245,"<"&C92)/COUNT(Data!$BI$4:$BI$23245) -> 0.11982618
A93: 10% to 15% | B93: 0.1 | C93: 0.15 | D93: =COUNTIFS('Trade Log'!$O$5:$O$571,">="&B93,'Trade Log'!$O$5:$O$571,"<"&C93)/COUNT('Trade Log'!$O$5:$O$571) -> 0.10758377 | E93: =COUNTIFS(Data!$BI$4:$BI$23245,">="&B93,Data!$BI$4:$BI$23245,"<"&C93)/COUNT(Data!$BI$4:$BI$23245) -> 0.094441098
...

Sheet Trade Log
A1: Trade Log — every trade of the frozen configuration, A to Z (chronological)
A2: Forward-test candidate — not validated. Net return = gross − 0.585% round trip. Excess vs benchmark = gross return − NIFTY 500 price-index return between entry and exit dates. Price path = daily Close ÷ entry Open, entry to exit.
A4: Entry date | B4: Symbol | C4: Company | D4: Sector | E4: Filing timestamp (IST) | F4: Event day | G4: Entry price (Open) | H4: Exit date | I4: Exit price (Close) | J4: Holding days (sessions) | K4: SUE | L4: SUE quintile | M4: Gross return | N4: Cost | O4: Net return | P4: Excess vs NIFTY 500 | Q4: Period | R4: Result | S4: Price path
A5: 44419 | B5: SHREECEM | C5: SHREE CEMENT LIMITED | D5: Cement & Cement Products | E5: 44417.767 | F5: 44418 | G5: 26650.973 | H5: 44509 | I5: 28623.867 | J5: 60 | K5: 2.0311596 | L5: 5 | M5: 0.074027106 | N5: 0.00585 | O5: 0.068177106 | P5: -0.045988315 | Q5: Discovery | R5: Win
A6: 44421 | B6: POWERGRID | C6: Power Grid Corporation of India Limited | D6: Power | E6: 44419.679 | F6: 44420 | G6: 106.78037 | H6: 44511 | I6: 107.45535 | J6: 60 | K6: 10.013007 | L6: 5 | M6: 0.0063211876 | N6: 0.00585 | O6: 0.0004711876 | P6: -0.089361094 | Q6: Discovery | R6: Win
A7: 44421 | B7: HINDALCO | C7: Hindalco Industries Limited | D7: Metals | E7: 44419.725 | F7: 44420 | G7: 422.83556 | H7: 44511 | I7: 438.8345 | J7: 60 | K7: 3.0824236 | L7: 5 | M7: 0.037837271 | N7: 0.00585 | O7: 0.031987271 | P7: -0.057845011 | Q7: Discovery | R7: Win
A8: 44421 | B8: ASTERDM | C8: Aster DM Quality Care Limited | D8: Healthcare Services | E8: 44420.552 | F8: 44420 | G8: 125.29557 | H8: 44511 | I8: 153.65512 | J8: 60 | K8: 2.6427573 | L8: 5 | M8: 0.22634116 | N8: 0.00585 | O8: 0.22049116 | P8: 0.13065888 | Q8: Discovery | R8: Win
A9: 44421 | B9: SUPRAJIT | C9: Suprajit Engineering Limited | D9: Automobile | E9: 44420.394 | F9: 44420 | G9: 308.38685 | H9: 44511 | I9: 351.39987 | J9: 60 | K9: 1.8476518 | L9: 5 | M9: 0.13947749 | N9: 0.00585 | O9: 0.13362749 | P9: 0.043795207 | Q9: Discovery | R9: Win
A10: 44421 | B10: PTC | C10: PTC India Limited | D10: Power | E10: 44420.497 | F10: 44420 | G10: 65.20744 | H10: 44511 | I10: 84.215179 | J10: 60 | K10: 1.6833341 | L10: 5 | M10: 0.29149648 | N10: 0.00585 | O10: 0.28564648 | P10: 0.1958142 | Q10: Discovery | R10: Win
A11: 44424 | B11: CUMMINSIND | C11: Cummins India Limited | D11: Industrial Manufacturing | E11: 44420.693 | F11: 44421 | G11: 914.80906 | H11: 44512 | I11: 858.83167 | J11: 60 | K11: 3.8741236 | L11: 5 | M11: -0.061190245 | N11: 0.00585 | O11: -0.067040245 | P11: -0.16837676 | Q11: Discovery | R11: Loss
A12: 44424 | B12: TATASTEEL | C12: Tata Steel Limited | D12: Metals | E12: 44420.791 | F12: 44421 | G12: 127.97396 | H12: 44512 | I12: 111.00708 | J12: 60 | K12: 2.5486866 | L12: 5 | M12: -0.13258074 | N12: 0.00585 | O12: -0.13843074 | P12: -0.23976725 | Q12: Discovery | R12: Loss
A13: 44424 | B13: GRASIM | C13: Grasim Industries Limited | D13: Cement & Cement Products | E13: 44421.628 | F13: 44421 | G13: 1460.0643 | H13: 44512 | I13: 1810.2985 | J13: 60 | K13: 2.3036121 | L13: 5 | M13: 0.23987587 | N13: 0.00585 | O13: 0.23402587 | P13: 0.13268935 | Q13: Discovery | R13: Win
A14: 44424 | B14: KNRCON | C14: KNR Constructions Limited | D14: Construction | E14: 44420.698 | F14: 44421 | G14: 285.10595 | H14: 44512 | I14: 283.06369 | J14: 60 | K14: 2.0313248 | L14: 5 | M14: -0.0071631521 | N14: 0.00585 | O14: -0.013013152 | P14: -0.11434967 | Q14: Discovery | R14: Loss
A15: 44424 | B15: SUNDRMFAST | C15: Sundram Fasteners Limited | D15: Automobile | E15: 44420.699 | F15: 44421 | G15: 753.74181 | H15: 44512 | I15: 793.16162 | J15: 60 | K15: 1.9948311 | L15: 5 | M15: 0.052298826 | N15: 0.00585 | O15: 0.046448826 | P15: -0.054887688 | Q15: Discovery | R15: Win
A16: 44424 | B16: REDINGTON | C16: Redington Limited | D16: Services | E16: 44421.547 | F16: 44421 | G16: 150.95597 | H16: 44512 | I16: 127.36713 | J16: 60 | K16: 1.8469303 | L16: 5 | M16: -0.15626307 | N16: 0.00585 | O16: -0.16211307 | P16: -0.26344959 | Q16: Discovery | R16: Loss
... A571: 46157 | B571: ECLERX | C571: eClerx Services Limited | D571: IT | E571: 46155.822 | F571: 46156 | G571: 1535.1489 | H571: 46245 | I571: 1794.6051 | J571: 60 | K571: 1.7003528 | L571: 5 | M571: 0.16901044 | N571: 0.00585 | O571: 0.16316044 | P571: 0.11796999 | Q571: Holdout | R571: Win
A572: TOTALS | B572: =COUNTA(B5:B571) -> 567 | M572: =AVERAGE(M5:M571) -> 0.051934937 | N572: avg net → | O572: =AVERAGE(O5:O571) -> 0.046084937 | P572: =AVERAGE(P5:P571) -> 0.022942353 | Q572: win rate → | R572: =COUNTIF(R5:R571,"Win")/COUNTA(R5:R571) -> 0.58377425
A574: Source: corrected/trade_ledger_corrected.csv; price paths from pead/cache/px (NSE-calendar filtered) · Built from CORRECTED_REPORT.md (revision 2) outputs · Workbook generated 2026-09-23

Sheet Risk Diagnostics
A1: Risk & Robustness Diagnostics
A2: Forward-test candidate — not validated. Signal tests use the cross-sectional event sample; KT5 is the only portfolio-level kill test.
A4: Tail risk (daily NAV returns)
A5: Metric | B5: Full Period | C5: Discovery | D5: Holdout
A6: VaR 95% (1-day) | B6: =Data!C27 -> 0.016145473 | C6: =Data!D27 -> 0.014830713 | D6: =Data!E27 -> 0.016855544
A7: CVaR 95% (1-day) | B7: =Data!C28 -> 0.025294984 | C7: =Data!D28 -> 0.023651239 | D7: =Data!E28 -> 0.02599451
A8: Skewness (daily) | B8: =Data!C29 -> -0.84651235 | C8: =Data!D29 -> -0.86821847 | D8: =Data!E29 -> -0.80798231
A9: Excess kurtosis (daily) | B9: =Data!C30 -> 4.3629052 | C9: =Data!D30 -> 3.9249457 | D9: =Data!E30 -> 4.5016245
A10: Annualised volatility | B10: =Data!C14 -> 0.16071962 | C10: =Data!D14 -> 0.14845989 | D10: =Data!E14 -> 0.16698793
A11: Maximum drawdown | B11: =Data!C22 -> -0.23675278 | C11: =Data!D22 -> -0.19281551 | D11: =Data!E22 -> -0.24950465
A13: Signal breakdown — Q5 minus Q1, 60 trading days, excess vs event universe
A14: Cut | B14: Q5 n | C14: Q1 n | D14: Q5 | E14: Q1 | F14: Spread | G14: p-value | H14: Folds + | I14: Folds | J14: Ex-best fold
A15: All events | B15: =Data!BY4 -> 1427 | C15: =Data!BZ4 -> 1503 | D15: =Data!CA4 -> 0.014148459 | E15: =Data!CB4 -> -0.015953365 | F15: =Data!CC4 -> 0.030101824 | G15: =Data!CD4 -> 1.2828659e-07 | H15: =Data!CE4 -> 17 | I15: =Data!CF4 -> 20 | J15: =Data!CG4 -> 0.030570657
A16: Discovery (≤ 2023) | B16: =Data!BY5 -> 635 | C16: =Data!BZ5 -> 709 | D16: =Data!CA5 -> 0.017005464 | E16: =Data!CB5 -> -0.017284883 | F16: =Data!CC5 -> 0.034290347 | G16: =Data!CD5 -> 0.00013057945 | H16: =Data!CE5 -> 8 | I16: =Data!CF5 -> 10 | J16: =Data!CG5 -> 0.034967031
A17: Holdout (≥ 2024) | B17: =Data!BY6 -> 792 | C17: =Data!BZ6 -> 794 | D17: =Data!CA6 -> 0.011857805 | E17: =Data!CB6 -> -0.01476439 | F17: =Data!CC6 -> 0.026622195 | G17: =Data!CD6 -> 0.00030198287 | H17: =Data!CE6 -> 9 | I17: =Data!CF6 -> 10 | J17: =Data!CG6 -> 0.021958328
A18: Size: Small (turnover tercile) | B18: =Data!BY16 -> 358 | C18: =Data!BZ16 -> 595 | D18: =Data!CA16 -> 0.013769867 | E18: =Data!CB16 -> -0.028702101 | F18: =Data!CC16 -> 0.042471968 | G18: =Data!CD16 -> 2.7411364e-05 | H18: =Data!CE16 -> 19 | I18: =Data!CF16 -> 20 | J18: =Data!CG16 -> 0.040572279
A19: Size: Mid | B19: =Data!BY17 -> 483 | C19: =Data!BZ17 -> 504 | D19: =Data!CA17 -> 0.017130432 | E19: =Data!CB17 -> -0.0051172498 | F19: =Data!CC17 -> 0.022247681 | G19: =Data!CD17 -> 0.037625719 | H19: =Data!CE17 -> 13 | I19: =Data!CF17 -> 20 | J19: =Data!CG17 -> 0.0177489
A20: Size: Large | B20: =Data!BY18 -> 586 | C20: =Data!BZ18 -> 404 | D20: =Data!CA18 -> 0.011921912 | E20: =Data!CB18 -> -0.010695701 | F20: =Data!CC18 -> 0.022617613 | G20: =Data!CD18 -> 0.012214283 | H20: =Data!CE18 -> 14 | I20: =Data!CF18 -> 19 | J20: =Data!CG18 -> 0.022999998
A21: Non-Financials (traded universe) | B21: =Data!BY14 -> 1114 | C21: =Data!BZ14 -> 1403 | D21: =Data!CA14 -> 0.014836427 | E21: =Data!CB14 -> -0.019594424 | F21: =Data!CC14 -> 0.034430851 | G21: =Data!CD14 -> 3.6533215e-08 | H21: =Data!CE14 -> 17 | I21: =Data!CF14 -> 20 | J21: =Data!CG14 -> 0.035126845
A22: Financials (EXCLUDED) | B22: =Data!BY15 -> 313 | C22: =Data!BZ15 -> 100 | D22: =Data!CA15 -> 0.011699911 | E22: =Data!CB15 -> 0.035130698 | F22: =Data!CC15 -> -0.023430787 | G22: =Data!CD15 -> 0.19359791 | H22: =Data!CE15 -> 9 | I22: =Data!CF15 -> 17 | J22: =Data!CG15 -> -0.024415901
A23: Financials excluded: banks, NBFCs, housing finance, insurers, AMCs, exchanges/market infrastructure and rating agencies, identified by the XBRL pipeline 'fin' flag (taxonomy BANKING/NBFC or industry = FINANCIAL SERVICES). Provision-driven profits make a seasonal-random-walk SUE a poor surprise proxy; the financials spread is negative and not significant.
A26: Kill tests (corrected)
A27: Test | B27: Perturbation | E27: Result | J27: Pass?
A28: =Data!CJ4 -> KT1 | B28: =Data!CK4 -> Drop top-2 quarterly folds (2021Q3 & 2022Q1) | E28: =Data!CL4 -> fold-mean +3.45% -> +2.75%, folds+ 83.3%; event-level spread +2.62% | J28: =IF(Data!CM4,"PASS","FAIL") -> PASS
A29: =Data!CJ5 -> KT2 | B29: =Data!CK5 -> Drop 2021 | E29: =Data!CL5 -> spread +2.88%, p=7.9e-07 | J29: =IF(Data!CM5,"PASS","FAIL") -> PASS
A30: =Data!CJ6 -> KT3 | B30: =Data!CK6 -> Mid + Large caps only | E30: =Data!CL6 -> spread +2.19%, p=0.0017 | J30: =IF(Data!CM6,"PASS","FAIL") -> PASS
A31: =Data!CJ7 -> KT4 | B31: =Data!CK7 -> Exclude Layer-4-seen events | E31: =Data!CL7 -> spread +3.05%, folds+ 85.0% | J31: =IF(Data!CM7,"PASS","FAIL") -> PASS
A32: =Data!CJ8 -> KT5 | B32: =Data!CK8 -> 1.000% round-trip cost (portfolio) | E32: =Data!CL8 -> full excess +4.06%, HOLDOUT excess -0.88% | J32: =IF(Data!CM8,"PASS","FAIL") -> FAIL
A33: =Data!CJ9 -> KT6 | B33: =Data!CK9 -> 8Q / expanding threshold windows | E33: =Data!CL9 -> 8Q +2.91%, expanding +2.83% | J33: =IF(Data!CM9,"PASS","FAIL") -> PASS
A34: =Data!CJ10 -> KT7 | B34: =Data!CK10 -> Horizon jitter 40d / 90d | E34: =Data!CL10 -> 40d +1.82%, 90d +3.92% | J34: =IF(Data!CM10,"PASS","FAIL") -> PASS
A35: Reading: every signal-level test passes; the portfolio-level cost test (KT5) fails because at 1.0% round-trip cost the holdout book trails NIFTY 500. KT1 compares the mean of quarterly fold spreads with and without the two best quarters (2021Q3, 2022Q1).
A38: Cost sensitivity
A39: Round-trip cost | B39: Full CAGR | C39: Full excess* | D39: Full Sharpe (rf 0) | E39: Full max DD | F39: Holdout CAGR | G39: Holdout excess*
A40: =Data!BO4 -> 0.003 | B40: =Data!BP4 -> 0.18416048 | C40: =Data!BQ4 -> 0.071325899 | D40: =Data!BR4 -> 1.1503883 | E40: =Data!BS4 -> -0.2328879 | F40: =Data!BT4 -> 0.098906978 | G40: =Data!BU4 -> 0.019972509
A41: =Data!BO5 -> 0.00585 | B41: =Data!BP5 -> 0.17155034 | C41: =Data!BQ5 -> 0.058715761 | D41: =Data!BR5 -> 1.0827253 | E41: =Data!BS5 -> -0.23675278 | F41: =Data!BT5 -> 0.087085033 | G41: =Data!BU5 -> 0.0081505638
A42: =Data!BO6 -> 0.01 | B42: =Data!BP6 -> 0.15342996 | C42: =Data!BQ6 -> 0.040595379 | D42: =Data!BR6 -> 0.98408992 | E42: =Data!BS6 -> -0.24234357 | F42: =Data!BT6 -> 0.070100271 | G42: =Data!BU6 -> -0.0088341983
A44: Capacity — share of trades that fit within 1% / 5% of 20-day median traded value
A62: Source: corrected/period_metrics_corrected.csv, signal_cells.csv, kill_tests_corrected.csv, cost_sensitivity_corrected.csv, capacity_curve_corrected.csv · Built from CORRECTED_REPORT.md (revision 2) outputs · Workbook generated 2026-09-23

Sheet Methodology
A1: Methodology & Disclaimers
A4: Status
A5: DISCOVERY — NOT VALIDATED. StackFlow PEAD V2 is a FORWARD-TEST CANDIDATE. The cross-sectional signal is confirmed; the long-only trading strategy is not validated. Nothing in this workbook is investment advice or a live-trading recommendation.
A7: Signal — Standardised Unexpected Earnings (SUE)
A8: SUE_q = (PAT_q − PAT of the same fiscal quarter one year earlier) ÷ standard deviation of the YoY PAT changes of the 8 prior quarters (at least 6 required). Seasonal random walk: NO analyst estimates are used. YoY is matched by fiscal quarter-end date (audit fix 5), so gaps in the XBRL series never compare the wrong quarters.
A9: Ex-ante buckets (model M1): for an event on day T, quintile cut-offs are the 20/40/60/80th percentiles of SUE across all qualifying events with event day in [T−365, T), minimum 150 prior events (pre-registration said 200; disclosed deviation; with 200 the spread is unchanged). Events 2021-08-10 → 2022-02-09 use truncated windows because data begins 2021-02-10. The strategy buys Q5 only.
A11: Universe and filters
A12: NSE equities with quarterly XBRL PAT (earliest parseable filing per company-quarter, Consolidated first, Standalone fallback). 20-session average traded value before the event day ≥ INR 1 crore; entry Open > INR 50. Prices restricted to NSE sessions (phantom zero-volume holiday rows removed, audit fix 6). Financial sector excluded by the XBRL pipeline 'fin' flag: taxonomy BANKING/NBFC or industry FINANCIAL SERVICES — banks, NBFCs, housing finance, insurers, AMCs, exchanges, rating agencies (audit fix 4). Universe = 421 symbols with a price history today: survivorship bias is not removed.
A14: Entry / exit timing (reconciled rule, TIMING_RULES.md)
A15: Case A — filing ≤ 15:30 IST on a session day D: event day = D; entry = OPEN of the next session.
A16: Case B — filing > 15:30 IST on a session day D: event day = next session; entry = OPEN of the session after that.
A17: Case C — filing on a weekend/holiday: ≤ 15:30 IST → event day = first session D1, entry = OPEN of D2; > 15:30 IST → event day = D2, entry = OPEN of D3 (as coded; conservative).
... A45: Source: CORRECTED_REPORT.md (rev 2), live_config_pead_v2_corrected.md, TIMING_RULES.md, AUDIT_REPORT.md · Built from CORRECTED_REPORT.md (revision 2) outputs · Workbook generated 2026-09-23

Sheet Data
A1: Period metrics (corrected/period_metrics_corrected.csv) | I1: Daily NAV, rebased to 100 (corrected/nav_daily_corrected.csv) | T1: Monthly returns (corrected/monthly_returns_corrected.csv) | AA1: Calendar-year returns (corrected/yearly_returns_corrected.csv) | AH1: Rolling 12-month (252-session) returns (corrected/rolling_12m_corrected.csv) | AM1: Signal: quarterly Q5-Q1 spread, 60d, xs event universe (corrected/signal_folds_60d.csv) | AU1: Portfolio: quarterly return vs NIFTY 500 (corrected/quarterly_portfolio_excess_corrected.csv) | BB1: Placebo: 40 random books, same mechanics (corrected/placebo_random_books.csv) | BI1: Placebo trade-level net returns (corrected/placebo_trade_returns.csv) | BK1: Capacity curve (corrected/capacity_curve_corrected.csv) | BO1: Cost sensitivity (corrected/cost_sensitivity_corrected.csv) | BX1: Signal cells, 60d unless stated (corrected/signal_cells.csv) | CJ1: Kill tests (corrected/kill_tests_corrected.csv) | CP1: Per-trade price path: Close / entry Open, entry day to exit day (calendar-filtered pead/cache/px)
P2: band height = | Q2: 225
A3: key | B3: metric | C3: Full Period | D3: Discovery | E3: Holdout | F3: Discovery (calendar split of full book) | G3: Holdout (calendar split of full book) | I3: date | J3: strategy_nav | K3: nifty500 | L3: strategy_dd | M3: nifty500_dd | N3: positions_held | O3: period | P3: band_discovery | Q3: band_holdout | T3: month_end | U3: year | V3: month | W3: strategy | X3: nifty500 | Y3: excess | AA3: year | AB3: window | AC3: strategy | AD3: nifty500 | AE3: excess | AF3: trades_entered | AH3: date | AI3: strategy_12m | AJ3: nifty500_12m | AK3: excess_12m | AM3: qtr | AN3: period | AO3: n_hi | AP3: n_lo | AQ3: spread | AR3: positive | AS3: negative | AU3: quarter | AV3: strategy | AW3: nifty500 | AX3: excess | AY3: positive | AZ3: negative | BB3: draw | BC3: trades | BD3: cagr | BE3: excess_cagr | BF3: sharpe_rf0 | BG3: holdout_excess_cagr | BI3: net_return | BK3: aum_cr | BL3: pct_trades_within_1pct_adv | BM3: pct_trades_within_5pct_adv | BO3: round_trip_cost | BP3: full_cagr | BQ3: full_excess | BR3: full_sharpe_rf0 | BS3: full_max_dd | BT3: holdout_cagr | BU3: holdout_excess | BX3: label | BY3: n_q5 | BZ3: n_q1 | CA3: q5_pct | CB3: q1_pct | CC3: spread_pct | CD3: p_val | CE3: folds_pos | CF3: folds_total | CG3: spread_ex_best_pct | CH3: inversions | CJ3: test | CK3: perturbation | CL3: result | CM3: passed | CP3: trade_id | CQ3: s0 | CR3: s1 | CS3: s2 | CT3: s3 | CU3: s4 | CV3: s5 | CW3: s6 | CX3: s7 | CY3: s8 | CZ3: s9 | DA3: s10 | DB3: s11 | DC3: s12 | DD3: s13 | DE3: s14 | DF3: s15 | DG3: s16 | DH3: s17 | DI3: s18 | DJ3: s19 | DK3: s20 | DL3: s21 | DM3: s22 | DN3: s23 | DO3: s24 | DP3: s25 | DQ3: s26 | DR3: s27 | DS3: s28 | DT3: s29 | DU3: s30 | DV3: s31 | DW3: s32 | DX3: s33 | DY3: s34 | DZ3: s35 | EA3: s36 | EB3: s37 | EC3: s38 | ED3: s39 | EE3: s40 | EF3: s41 | EG3: s42 | EH3: s43 | EI3: s44 | EJ3: s45 | EK3: s46 | EL3: s47 | EM3: s48 | EN3: s49 | EO3: s50 | EP3: s51 | EQ3: s52 | ER3: s53 | ES3: s54 | ET3: s55 | EU3: s56 | EV3: s57 | EW3: s58 | EX3: s59 | EY3: s60
A4: start | B4: Window start | C4: 2021-08-11 | D4: 2021-08-11 | E4: 2024-01-17 | F4: 2021-08-11 | G4: 2023-12-29 | I4: 44419 | J4: 100 | K4: 100 | L4: 0 | M4: 0 | N4: 1 | O4: Discovery | P4: =IF(O4="Discovery",$Q$2,0) -> 225 | Q4: =IF(O4="Holdout",$Q$2,0) -> 0 | T4: 44439 | U4: 2021 | V4: 8 | W4: 0.017963758 | X4: 0.048956693 | Y4: -0.030992935 | AA4: 2021 | AB4: 2021-08-11 to 2021-12-31 | AC4: 0.071650172 | AD4: 0.080686482 | AE4: -0.0090363098 | AF4: 37 | AH4: 44790 | AI4: 0.12626574 | AJ4: 0.10827619 | AK4: 0.017989547 | AM4: 2021Q3 | AN4: Discovery | AO4: 19 | AP4: 14 | AQ4: 0.10896649 | AR4: =MAX(AQ4,0) -> 0.10896649 | AS4: =MIN(AQ4,0) -> 0 | AU4: 2021Q3 | AV4: 0.025965752 | AW4: 0.084754496 | AX4: -0.058788744 | AY4: =MAX(AX4,0) -> 0 | AZ4: =MIN(AX4,0) -> -0.058788744 | BB4: 1 | BC4: 583 | BD4: 0.072191984 | BE4: -0.040295949 | BF4: 0.51430182 | BG4: -0.024128245 | BI4: -0.079794257 | BK4: 0.5 | BL4: 0.98412698 | BM4: 1 | BO4: 0.003 | BP4: 0.18416048 | BQ4: 0.071325899 | BR4: 1.1503883 | BS4: -0.2328879 | BT4: 0.098906978 | BU4: 0.019972509 | BX4: Primary 60d (all) | BY4: 1427 | BZ4: 1503 | CA4: 0.014148459 | CB4: -0.015953365 | CC4: 0.030101824 | CD4: 1.2828659e-07 | CE4: 17 | CF4: 20 | CG4: 0.030570657 | CH4: 0 | CJ4: KT1 | CK4: Drop top-2 quarterly folds (2021Q3 & 2022Q1) | CL4: fold-mean +3.45% -> +2.75%, folds+ 83.3%; event-level spread +2.62% | CM4: TRUE | CP4: T0001 | CQ4: 0.97547308 | CR4: 0.97714487 | CS4: 0.97741683 | CT4: 0.95456742 | CU4: 0.96271352 | CV4: 0.96738187 | CW4: 0.96605365 | CX4: 0.95483909 | CY4: 0.96391496 | CZ4: 0.96594709 | DA4: 0.97578726 | DB4: 0.98834287 | DC4: 0.9979 | DD4: 1.0394231 | DE4: 1.0464174 | DF4: 1.1142108 | DG4: 1.1185302 | DH4: 1.1220117 | DI4: 1.1263494 | DJ4: 1.1315378 | DK4: 1.1270017 | DL4: 1.1267076 | DM4: 1.1265296 | DN4: 1.1405639 | DO4: 1.1266084 | DP4: 1.1228898 | DQ4: 1.1060774 | DR4: 1.1045342 | DS4: 1.0947087 | DT4: 1.0993661 | DU4: 1.0807202 | DV4: 1.0830792 | DW4: 1.0745158 | DX4: 1.07964 | DY4: 1.0619713 | DZ4: 1.0692469 | EA4: 1.0762189 | EB4: 1.057007 | EC4: 1.032877 | ED4: 1.031025 | EE4: 1.019921 | EF4: 1.029669 | EG4: 1.0180342 | EH4: 1.0220723 | EI4: 1.0272442 | EJ4: 1.0358735 | EK4: 1.0177035 | EL4: 1.0089068 | EM4: 1.0148335 | EN4: 1.0192246 | EO4: 1.0022046 | EP4: 1.0206835 | EQ4: 1.0328036 | ER4: 1.0359379 | ES4: 1.0521862 | ET4: 1.0709442 | EU4: 1.0607441 | EV4: 1.0648741 | EW4: 1.0673231 | EX4: 1.0849365 | EY4: 1.0740271
